Site is down (first notice): https://thisisdefinitelynotgoingtobearealworkingurl.com
Error sending email.
Exception in thread Thread-1:
Traceback (most recent call last):
  File "/home/charles/uptime/vp/lib/python3.6/site-packages/urllib3/connection.py", line 160, in _new_conn
    (self._dns_host, self.port), self.timeout, **extra_kw
  File "/home/charles/uptime/vp/lib/python3.6/site-packages/urllib3/util/connection.py", line 61, in create_connection
    for res in socket.getaddrinfo(host, port, family, socket.SOCK_STREAM):
  File "/home/charles/.pyenv/versions/miniconda3-4.3.30/lib/python3.6/socket.py", line 745, in getaddrinfo
    for res in _socket.getaddrinfo(host, port, family, type, proto, flags):
socket.gaierror: [Errno -2] Name or service not known

During handling of the above exception, another exception occurred:

Traceback (most recent call last):
  File "/home/charles/uptime/vp/lib/python3.6/site-packages/urllib3/connectionpool.py", line 677, in urlopen
    chunked=chunked,
  File "/home/charles/uptime/vp/lib/python3.6/site-packages/urllib3/connectionpool.py", line 381, in _make_request
    self._validate_conn(conn)
  File "/home/charles/uptime/vp/lib/python3.6/site-packages/urllib3/connectionpool.py", line 976, in _validate_conn
    conn.connect()
  File "/home/charles/uptime/vp/lib/python3.6/site-packages/urllib3/connection.py", line 308, in connect
    conn = self._new_conn()
  File "/home/charles/uptime/vp/lib/python3.6/site-packages/urllib3/connection.py", line 172, in _new_conn
    self, "Failed to establish a new connection: %s" % e
urllib3.exceptions.NewConnectionError: <urllib3.connection.HTTPSConnection object at 0x7f3a67c35828>: Failed to establish a new connection: [Errno -2] Name or service not known

During handling of the above exception, another exception occurred:

Traceback (most recent call last):
  File "/home/charles/uptime/vp/lib/python3.6/site-packages/requests/adapters.py", line 449, in send
    timeout=timeout
  File "/home/charles/uptime/vp/lib/python3.6/site-packages/urllib3/connectionpool.py", line 725, in urlopen
    method, url, error=e, _pool=self, _stacktrace=sys.exc_info()[2]
  File "/home/charles/uptime/vp/lib/python3.6/site-packages/urllib3/util/retry.py", line 439, in increment
    raise MaxRetryError(_pool, url, error or ResponseError(cause))
urllib3.exceptions.MaxRetryError: HTTPSConnectionPool(host='thisisdefinitelynotgoingtobearealworkingurl.com', port=443): Max retries exceeded with url: / (Caused by NewConnectionError('<urllib3.connection.HTTPSConnection object at 0x7f3a67c35828>: Failed to establish a new connection: [Errno -2] Name or service not known',))

During handling of the above exception, another exception occurred:

Traceback (most recent call last):
  File "/home/charles/uptime/uptime.py", line 78, in site_up
    r = requests.get(url)
  File "/home/charles/uptime/vp/lib/python3.6/site-packages/requests/api.py", line 76, in get
    return request('get', url, params=params, **kwargs)
  File "/home/charles/uptime/vp/lib/python3.6/site-packages/requests/api.py", line 61, in request
    return session.request(method=method, url=url, **kwargs)
  File "/home/charles/uptime/vp/lib/python3.6/site-packages/requests/sessions.py", line 530, in request
    resp = self.send(prep, **send_kwargs)
  File "/home/charles/uptime/vp/lib/python3.6/site-packages/requests/sessions.py", line 643, in send
    r = adapter.send(request, **kwargs)
  File "/home/charles/uptime/vp/lib/python3.6/site-packages/requests/adapters.py", line 516, in send
    raise ConnectionError(e, request=request)
requests.exceptions.ConnectionError: HTTPSConnectionPool(host='thisisdefinitelynotgoingtobearealworkingurl.com', port=443): Max retries exceeded with url: / (Caused by NewConnectionError('<urllib3.connection.HTTPSConnection object at 0x7f3a67c35828>: Failed to establish a new connection: [Errno -2] Name or service not known',))

During handling of the above exception, another exception occurred:

Traceback (most recent call last):
  File "/home/charles/.pyenv/versions/miniconda3-4.3.30/lib/python3.6/threading.py", line 916, in _bootstrap_inner
    self.run()
  File "/home/charles/.pyenv/versions/miniconda3-4.3.30/lib/python3.6/threading.py", line 864, in run
    self._target(*self._args, **self._kwargs)
  File "/home/charles/uptime/uptime.py", line 90, in site_up
    site_status_down(url)
  File "/home/charles/uptime/uptime.py", line 62, in site_status_down
    gmail_site_down(url)
  File "/home/charles/uptime/uptime_gmail.py", line 53, in gmail_site_down
    send_email(subject, body)
  File "/home/charles/uptime/uptime_gmail.py", line 42, in send_email
    server.login(gmail_user, gmail_password)
  File "/home/charles/.pyenv/versions/miniconda3-4.3.30/lib/python3.6/smtplib.py", line 730, in login
    raise last_exception
  File "/home/charles/.pyenv/versions/miniconda3-4.3.30/lib/python3.6/smtplib.py", line 721, in login
    initial_response_ok=initial_response_ok)
  File "/home/charles/.pyenv/versions/miniconda3-4.3.30/lib/python3.6/smtplib.py", line 642, in auth
    raise SMTPAuthenticationError(code, resp)
smtplib.SMTPAuthenticationError: (535, b'5.7.8 Username and Password not accepted. Learn more at\n5.7.8  https://support.google.com/mail/?p=BadCredentials o11sm8547057pjq.54 - gsmtp')

Traceback (most recent call last):
  File "/home/charles/uptime/uptime.py", line 112, in <module>
    main()
  File "/home/charles/uptime/uptime.py", line 45, in main
    time.sleep(1)
KeyboardInterrupt
Exception ignored in: <module 'threading' from '/home/charles/.pyenv/versions/miniconda3-4.3.30/lib/python3.6/threading.py'>
Traceback (most recent call last):
  File "/home/charles/.pyenv/versions/miniconda3-4.3.30/lib/python3.6/threading.py", line 1294, in _shutdown
    t.join()
  File "/home/charles/.pyenv/versions/miniconda3-4.3.30/lib/python3.6/threading.py", line 1056, in join
    self._wait_for_tstate_lock()
  File "/home/charles/.pyenv/versions/miniconda3-4.3.30/lib/python3.6/threading.py", line 1072, in _wait_for_tstate_lock
    elif lock.acquire(block, timeout):
KeyboardInterrupt
